/opt/conda/envs/layoutlmv3/lib/python3.7/site-packages/torch/distributed/launch.py:188: FutureWarning: The module torch.distributed.launch is deprecated
and will be removed in future. Use torchrun.
Note that --use_env is set by default in torchrun.
If your script expects `--local_rank` argument to be set, please
change it to read from `os.environ['LOCAL_RANK']` instead. See 
https://pytorch.org/docs/stable/distributed.html#launch-utility for 
further instructions

  FutureWarning,
WARNING:torch.distributed.run:
*****************************************
Setting OMP_NUM_THREADS environment variable for each process to be 1 in default, to avoid your system being overloaded, please further tune the variable for optimal performance in your application as needed. 
*****************************************
/opt/conda/envs/layoutlmv3/bin/python: can't open file './src/sikubert_finetune_title.py': [Errno 2] No such file or directory
/opt/conda/envs/layoutlmv3/bin/python: can't open file './src/sikubert_finetune_title.py': [Errno 2] No such file or directory
/opt/conda/envs/layoutlmv3/bin/python: can't open file './src/sikubert_finetune_title.py': [Errno 2] No such file or directory
/opt/conda/envs/layoutlmv3/bin/python: can't open file './src/sikubert_finetune_title.py': [Errno 2] No such file or directory
ERROR:torch.distributed.elastic.multiprocessing.api:failed (exitcode: 2) local_rank: 0 (pid: 38128) of binary: /opt/conda/envs/layoutlmv3/bin/python
Traceback (most recent call last):
  File "/opt/conda/envs/layoutlmv3/lib/python3.7/runpy.py", line 193, in _run_module_as_main
    "__main__", mod_spec)
  File "/opt/conda/envs/layoutlmv3/lib/python3.7/runpy.py", line 85, in _run_code
    exec(code, run_globals)
  File "/opt/conda/envs/layoutlmv3/lib/python3.7/site-packages/torch/distributed/launch.py", line 195, in <module>
    main()
  File "/opt/conda/envs/layoutlmv3/lib/python3.7/site-packages/torch/distributed/launch.py", line 191, in main
    launch(args)
  File "/opt/conda/envs/layoutlmv3/lib/python3.7/site-packages/torch/distributed/launch.py", line 176, in launch
    run(args)
  File "/opt/conda/envs/layoutlmv3/lib/python3.7/site-packages/torch/distributed/run.py", line 756, in run
    )(*cmd_args)
  File "/opt/conda/envs/layoutlmv3/lib/python3.7/site-packages/torch/distributed/launcher/api.py", line 132, in __call__
    return launch_agent(self._config, self._entrypoint, list(args))
  File "/opt/conda/envs/layoutlmv3/lib/python3.7/site-packages/torch/distributed/launcher/api.py", line 248, in launch_agent
    failures=result.failures,
torch.distributed.elastic.multiprocessing.errors.ChildFailedError: 
============================================================
./src/sikubert_finetune_title.py FAILED
------------------------------------------------------------
Failures:
[1]:
  time      : 2023-04-05_20:42:03
  host      : ai-platform-wlf1-ge10-1.idchb2az1.hb2.kwaidc.com
  rank      : 1 (local_rank: 1)
  exitcode  : 2 (pid: 38129)
  error_file: <N/A>
  traceback : To enable traceback see: https://pytorch.org/docs/stable/elastic/errors.html
[2]:
  time      : 2023-04-05_20:42:03
  host      : ai-platform-wlf1-ge10-1.idchb2az1.hb2.kwaidc.com
  rank      : 2 (local_rank: 2)
  exitcode  : 2 (pid: 38130)
  error_file: <N/A>
  traceback : To enable traceback see: https://pytorch.org/docs/stable/elastic/errors.html
[3]:
  time      : 2023-04-05_20:42:03
  host      : ai-platform-wlf1-ge10-1.idchb2az1.hb2.kwaidc.com
  rank      : 3 (local_rank: 3)
  exitcode  : 2 (pid: 38131)
  error_file: <N/A>
  traceback : To enable traceback see: https://pytorch.org/docs/stable/elastic/errors.html
------------------------------------------------------------
Root Cause (first observed failure):
[0]:
  time      : 2023-04-05_20:42:03
  host      : ai-platform-wlf1-ge10-1.idchb2az1.hb2.kwaidc.com
  rank      : 0 (local_rank: 0)
  exitcode  : 2 (pid: 38128)
  error_file: <N/A>
  traceback : To enable traceback see: https://pytorch.org/docs/stable/elastic/errors.html
============================================================
